<?xml version="1.0" encoding="utf-8"?>
<robot name="world_constraints" xmlns:xacro="http://www.ros.org/wiki/xacro">
    

    <xacro:property name="world_constraints" value="${True}" />
    
    <!-- Generate Constraint using these joints -->
    <gazebo>
        <!-- UNCOMMENT FOR FLOATING TEST -->
        <!-- <joint name="world_fixed" type="fixed">
            <parent>world</parent>
            <child>base</child>
        </joint> -->

        <link name="z_translation" />
        <joint name="world_z_trans_joint" type="prismatic">
            <parent>world</parent>
            <child>z_translation</child>
            <axis>
                <xyz>0 0 1</xyz>
                <limit>
                    <lower>-10</lower>
                    <upper>10</upper>
                </limit>
            </axis>
        </joint>
        <link name="x_translation" />
        <joint name="z_trans_x_trans_joint" type="prismatic">
            <parent>z_translation</parent>
            <child>x_translation</child>
            <axis>
                <xyz>1 0 0</xyz>
                <limit>
                    <lower>-10</lower>
                    <upper>100</upper>
                </limit>
            </axis>
        </joint>
        <!-- <link name="x_rotation" /> -->
        <!-- <joint name="x_rotation_joint" type="revolute">
            <parent>x_translation</parent>
            <child>x_rotation</child>
            <axis>
                <xyz>1 0 0</xyz>
                <limit>
                    <lower>${-PI/2}</lower>
                    <upper>${PI/2}</upper>
                </limit>
            </axis>
        </joint> -->
        <joint name="y_rotation_joint" type="revolute">
            <parent>x_translation</parent>
            <child>base</child>
            <axis>
                <xyz>0 1 0</xyz>
                <limit>
                    <lower>${-PI/12}</lower>
                    <upper>${PI/12}</upper>
                </limit>
            </axis>
        </joint>
    </gazebo>
</robot>