<?xml version="1.0" ?>
<!-- =================================================================================== -->
<!-- |    This document was autogenerated by xacro from /workspace/src/robot_descriptions/generic_quadruped_description/xacro/quadruped.xacro | -->
<!-- |    EDITING THIS FILE BY HAND IS NOT RECOMMENDED                                 | -->
<!-- =================================================================================== -->
<robot name="quadruped">
  <material name="black">
    <color rgba="0.0 0.0 0.0 1.0"/>
  </material>
  <material name="blue">
    <color rgba="0.0 0.0 0.8 1.0"/>
  </material>
  <material name="green">
    <color rgba="0.0 0.8 0.0 1.0"/>
  </material>
  <material name="grey">
    <color rgba="0.2 0.2 0.2 1.0"/>
  </material>
  <material name="silver">
    <color rgba="0.9137254901960784 0.9137254901960784 0.8470588235294118 1.0"/>
  </material>
  <material name="orange">
    <color rgba="1.0 0.4235294117647059 0.0392156862745098 1.0"/>
  </material>
  <material name="brown">
    <color rgba="0.8705882352941177 0.8117647058823529 0.7647058823529411 1.0"/>
  </material>
  <material name="red">
    <color rgba="0.8 0.0 0.0 1.0"/>
  </material>
  <material name="white">
    <color rgba="1.0 1.0 1.0 1.0"/>
  </material>
  <link name="base">
    <visual>
      <origin rpy="0 0 0" xyz="0 0 0"/>
      <geometry>
        <box size="1 1 1"/>
      </geometry>
      <material name="red"/>
    </visual>
    <collision>
      <origin rpy="0 0 0" xyz="0 0 0"/>
      <geometry>
        <box size="1 1 1"/>
      </geometry>
    </collision>
  </link>
  <link name="base_inertia">
    <inertial>
      <origin rpy="0 0 0" xyz="0 0 0"/>
      <mass value="1"/>
      <inertia ixx="0.16666666666666666" ixy="0" ixz="0" iyy="0.16666666666666666" iyz="0" izz="0.16666666666666666"/>
    </inertial>
  </link>
  <joint name="inertial_base_joint" type="fixed">
    <origin rpy="0.0 0.0 0.0" xyz="0.0 0 0"/>
    <parent link="base"/>
    <child link="base_inertia"/>
  </joint>
  <link name="FR_hip">
    <inertial>
      <origin rpy="0 0 0" xyz="0.125 0 0"/>
      <mass value="1"/>
      <inertia ixx="0.005000000000000001" ixy="0" ixz="0" iyy="0.007708333333333333" iyz="0" izz="0.007708333333333333"/>
    </inertial>
    <visual>
      <origin rpy="0 1.5707963267948966 0" xyz="0.125 0 0"/>
      <geometry>
        <cylinder length="0.25" radius="0.1"/>
      </geometry>
      <material name="">
        <color rgba="0.792156862745098 0.819607843137255 0.933333333333333 1"/>
      </material>
    </visual>
    <collision>
      <origin rpy="0 1.5707963267948966 0" xyz="0.125 0 0"/>
      <geometry>
        <cylinder length="0.25" radius="0.1"/>
      </geometry>
    </collision>
  </link>
  <joint name="FR_hip_joint" type="continuous">
    <origin rpy="1.5707963267948966 0.0 -1.5707963267948966" xyz="0.5 -0.5 0.0"/>
    <parent link="base"/>
    <child link="FR_hip"/>
    <axis xyz="0 0 1"/>
  </joint>
  <link name="FR_thigh">
    <inertial>
      <origin rpy="0 0 0" xyz="0.5 0 0"/>
      <mass value="1"/>
      <inertia ixx="0.005000000000000001" ixy="0" ixz="0" iyy="0.08583333333333333" iyz="0" izz="0.08583333333333333"/>
    </inertial>
    <visual>
      <origin rpy="0 1.5707963267948966 0" xyz="0.5 0 0"/>
      <geometry>
        <cylinder length="1" radius="0.1"/>
      </geometry>
      <material name="">
        <color rgba="0.792156862745098 0.819607843137255 0.933333333333333 1"/>
      </material>
    </visual>
    <collision>
      <origin rpy="0 1.5707963267948966 0" xyz="0.5 0 0"/>
      <geometry>
        <cylinder length="1" radius="0.1"/>
      </geometry>
    </collision>
  </link>
  <joint name="FR_thigh_joint" type="continuous">
    <origin rpy="1.5707963267948966 0.0 -1.5707963267948966" xyz="0.25 0 0"/>
    <parent link="FR_hip"/>
    <child link="FR_thigh"/>
    <axis xyz="0 0 1"/>
  </joint>
  <link name="FR_calf">
    <inertial>
      <origin rpy="0 0 0" xyz="0.5 0 0"/>
      <mass value="1"/>
      <inertia ixx="0.005000000000000001" ixy="0" ixz="0" iyy="0.08583333333333333" iyz="0" izz="0.08583333333333333"/>
    </inertial>
    <visual>
      <origin rpy="0 1.5707963267948966 0" xyz="0.5 0 0"/>
      <geometry>
        <cylinder length="1" radius="0.1"/>
      </geometry>
      <material name="">
        <color rgba="0.792156862745098 0.819607843137255 0.933333333333333 1"/>
      </material>
    </visual>
    <collision>
      <origin rpy="0 1.5707963267948966 0" xyz="0.5 0 0"/>
      <geometry>
        <cylinder length="1" radius="0.1"/>
      </geometry>
    </collision>
  </link>
  <joint name="FR_calf_joint" type="continuous">
    <origin rpy="0.0 0.0 0.0" xyz="1 0 0"/>
    <parent link="FR_thigh"/>
    <child link="FR_calf"/>
    <axis xyz="0 0 1"/>
  </joint>
  <link name="FR_foot">
    <inertial>
      <origin rpy="0 0 0" xyz="0 0 0"/>
      <mass value="1"/>
      <inertia ixx="0.004000000000000001" ixy="0" ixz="0" iyy="0.0025937500000000006" iyz="0" izz="0.0025937500000000006"/>
    </inertial>
    <visual>
      <origin rpy="0 0 0" xyz="0 0 0"/>
      <geometry>
        <sphere radius="0.1"/>
      </geometry>
      <material name="">
        <color rgba="0.792156862745098 0.819607843137255 0.933333333333333 1"/>
      </material>
    </visual>
    <collision>
      <origin rpy="0 0 0" xyz="0 0 0"/>
      <geometry>
        <sphere radius="0.1"/>
      </geometry>
    </collision>
  </link>
  <joint name="FR_foot" type="fixed">
    <origin rpy="0.0 0.0 0.0" xyz="1 0 0"/>
    <parent link="FR_calf"/>
    <child link="FR_foot"/>
  </joint>
  <link name="FL_hip">
    <inertial>
      <origin rpy="0 0 0" xyz="0.125 0 0"/>
      <mass value="1"/>
      <inertia ixx="0.005000000000000001" ixy="0" ixz="0" iyy="0.007708333333333333" iyz="0" izz="0.007708333333333333"/>
    </inertial>
    <visual>
      <origin rpy="0 1.5707963267948966 0" xyz="0.125 0 0"/>
      <geometry>
        <cylinder length="0.25" radius="0.1"/>
      </geometry>
      <material name="">
        <color rgba="0.792156862745098 0.819607843137255 0.933333333333333 1"/>
      </material>
    </visual>
    <collision>
      <origin rpy="0 1.5707963267948966 0" xyz="0.125 0 0"/>
      <geometry>
        <cylinder length="0.25" radius="0.1"/>
      </geometry>
    </collision>
  </link>
  <joint name="FL_hip_joint" type="continuous">
    <origin rpy="1.5707963267948966 0.0 1.5707963267948966" xyz="0.5 0.5 0.0"/>
    <parent link="base"/>
    <child link="FL_hip"/>
    <axis xyz="0 0 1"/>
  </joint>
  <link name="FL_thigh">
    <inertial>
      <origin rpy="0 0 0" xyz="0.5 0 0"/>
      <mass value="1"/>
      <inertia ixx="0.005000000000000001" ixy="0" ixz="0" iyy="0.08583333333333333" iyz="0" izz="0.08583333333333333"/>
    </inertial>
    <visual>
      <origin rpy="0 1.5707963267948966 0" xyz="0.5 0 0"/>
      <geometry>
        <cylinder length="1" radius="0.1"/>
      </geometry>
      <material name="">
        <color rgba="0.792156862745098 0.819607843137255 0.933333333333333 1"/>
      </material>
    </visual>
    <collision>
      <origin rpy="0 1.5707963267948966 0" xyz="0.5 0 0"/>
      <geometry>
        <cylinder length="1" radius="0.1"/>
      </geometry>
    </collision>
  </link>
  <joint name="FL_thigh_joint" type="continuous">
    <origin rpy="1.5707963267948966 0.0 -1.5707963267948966" xyz="0.25 0 0"/>
    <parent link="FL_hip"/>
    <child link="FL_thigh"/>
    <axis xyz="0 0 1"/>
  </joint>
  <link name="FL_calf">
    <inertial>
      <origin rpy="0 0 0" xyz="0.5 0 0"/>
      <mass value="1"/>
      <inertia ixx="0.005000000000000001" ixy="0" ixz="0" iyy="0.08583333333333333" iyz="0" izz="0.08583333333333333"/>
    </inertial>
    <visual>
      <origin rpy="0 1.5707963267948966 0" xyz="0.5 0 0"/>
      <geometry>
        <cylinder length="1" radius="0.1"/>
      </geometry>
      <material name="">
        <color rgba="0.792156862745098 0.819607843137255 0.933333333333333 1"/>
      </material>
    </visual>
    <collision>
      <origin rpy="0 1.5707963267948966 0" xyz="0.5 0 0"/>
      <geometry>
        <cylinder length="1" radius="0.1"/>
      </geometry>
    </collision>
  </link>
  <joint name="FL_calf_joint" type="continuous">
    <origin rpy="0.0 0.0 0.0" xyz="1 0 0"/>
    <parent link="FL_thigh"/>
    <child link="FL_calf"/>
    <axis xyz="0 0 1"/>
  </joint>
  <link name="FL_foot">
    <inertial>
      <origin rpy="0 0 0" xyz="0 0 0"/>
      <mass value="1"/>
      <inertia ixx="0.004000000000000001" ixy="0" ixz="0" iyy="0.0025937500000000006" iyz="0" izz="0.0025937500000000006"/>
    </inertial>
    <visual>
      <origin rpy="0 0 0" xyz="0 0 0"/>
      <geometry>
        <sphere radius="0.1"/>
      </geometry>
      <material name="">
        <color rgba="0.792156862745098 0.819607843137255 0.933333333333333 1"/>
      </material>
    </visual>
    <collision>
      <origin rpy="0 0 0" xyz="0 0 0"/>
      <geometry>
        <sphere radius="0.1"/>
      </geometry>
    </collision>
  </link>
  <joint name="FL_foot" type="fixed">
    <origin rpy="0.0 0.0 0.0" xyz="1 0 0"/>
    <parent link="FL_calf"/>
    <child link="FL_foot"/>
  </joint>
  <link name="RL_hip">
    <inertial>
      <origin rpy="0 0 0" xyz="0.125 0 0"/>
      <mass value="1"/>
      <inertia ixx="0.005000000000000001" ixy="0" ixz="0" iyy="0.007708333333333333" iyz="0" izz="0.007708333333333333"/>
    </inertial>
    <visual>
      <origin rpy="0 1.5707963267948966 0" xyz="0.125 0 0"/>
      <geometry>
        <cylinder length="0.25" radius="0.1"/>
      </geometry>
      <material name="">
        <color rgba="0.792156862745098 0.819607843137255 0.933333333333333 1"/>
      </material>
    </visual>
    <collision>
      <origin rpy="0 1.5707963267948966 0" xyz="0.125 0 0"/>
      <geometry>
        <cylinder length="0.25" radius="0.1"/>
      </geometry>
    </collision>
  </link>
  <joint name="RL_hip_joint" type="continuous">
    <origin rpy="1.5707963267948966 0.0 1.5707963267948966" xyz="-0.5 0.5 0.0"/>
    <parent link="base"/>
    <child link="RL_hip"/>
    <axis xyz="0 0 1"/>
  </joint>
  <link name="RL_thigh">
    <inertial>
      <origin rpy="0 0 0" xyz="0.5 0 0"/>
      <mass value="1"/>
      <inertia ixx="0.005000000000000001" ixy="0" ixz="0" iyy="0.08583333333333333" iyz="0" izz="0.08583333333333333"/>
    </inertial>
    <visual>
      <origin rpy="0 1.5707963267948966 0" xyz="0.5 0 0"/>
      <geometry>
        <cylinder length="1" radius="0.1"/>
      </geometry>
      <material name="">
        <color rgba="0.792156862745098 0.819607843137255 0.933333333333333 1"/>
      </material>
    </visual>
    <collision>
      <origin rpy="0 1.5707963267948966 0" xyz="0.5 0 0"/>
      <geometry>
        <cylinder length="1" radius="0.1"/>
      </geometry>
    </collision>
  </link>
  <joint name="RL_thigh_joint" type="continuous">
    <origin rpy="1.5707963267948966 0.0 -1.5707963267948966" xyz="0.25 0 0"/>
    <parent link="RL_hip"/>
    <child link="RL_thigh"/>
    <axis xyz="0 0 1"/>
  </joint>
  <link name="RL_calf">
    <inertial>
      <origin rpy="0 0 0" xyz="0.5 0 0"/>
      <mass value="1"/>
      <inertia ixx="0.005000000000000001" ixy="0" ixz="0" iyy="0.08583333333333333" iyz="0" izz="0.08583333333333333"/>
    </inertial>
    <visual>
      <origin rpy="0 1.5707963267948966 0" xyz="0.5 0 0"/>
      <geometry>
        <cylinder length="1" radius="0.1"/>
      </geometry>
      <material name="">
        <color rgba="0.792156862745098 0.819607843137255 0.933333333333333 1"/>
      </material>
    </visual>
    <collision>
      <origin rpy="0 1.5707963267948966 0" xyz="0.5 0 0"/>
      <geometry>
        <cylinder length="1" radius="0.1"/>
      </geometry>
    </collision>
  </link>
  <joint name="RL_calf_joint" type="continuous">
    <origin rpy="0.0 0.0 0.0" xyz="1 0 0"/>
    <parent link="RL_thigh"/>
    <child link="RL_calf"/>
    <axis xyz="0 0 1"/>
  </joint>
  <link name="RL_foot">
    <inertial>
      <origin rpy="0 0 0" xyz="0 0 0"/>
      <mass value="1"/>
      <inertia ixx="0.004000000000000001" ixy="0" ixz="0" iyy="0.0025937500000000006" iyz="0" izz="0.0025937500000000006"/>
    </inertial>
    <visual>
      <origin rpy="0 0 0" xyz="0 0 0"/>
      <geometry>
        <sphere radius="0.1"/>
      </geometry>
      <material name="">
        <color rgba="0.792156862745098 0.819607843137255 0.933333333333333 1"/>
      </material>
    </visual>
    <collision>
      <origin rpy="0 0 0" xyz="0 0 0"/>
      <geometry>
        <sphere radius="0.1"/>
      </geometry>
    </collision>
  </link>
  <joint name="RL_foot" type="fixed">
    <origin rpy="0.0 0.0 0.0" xyz="1 0 0"/>
    <parent link="RL_calf"/>
    <child link="RL_foot"/>
  </joint>
  <link name="RR_hip">
    <inertial>
      <origin rpy="0 0 0" xyz="0.125 0 0"/>
      <mass value="1"/>
      <inertia ixx="0.005000000000000001" ixy="0" ixz="0" iyy="0.007708333333333333" iyz="0" izz="0.007708333333333333"/>
    </inertial>
    <visual>
      <origin rpy="0 1.5707963267948966 0" xyz="0.125 0 0"/>
      <geometry>
        <cylinder length="0.25" radius="0.1"/>
      </geometry>
      <material name="">
        <color rgba="0.792156862745098 0.819607843137255 0.933333333333333 1"/>
      </material>
    </visual>
    <collision>
      <origin rpy="0 1.5707963267948966 0" xyz="0.125 0 0"/>
      <geometry>
        <cylinder length="0.25" radius="0.1"/>
      </geometry>
    </collision>
  </link>
  <joint name="RR_hip_joint" type="continuous">
    <origin rpy="1.5707963267948966 0.0 -1.5707963267948966" xyz="-0.5 -0.5 0.0"/>
    <parent link="base"/>
    <child link="RR_hip"/>
    <axis xyz="0 0 1"/>
  </joint>
  <link name="RR_thigh">
    <inertial>
      <origin rpy="0 0 0" xyz="0.5 0 0"/>
      <mass value="1"/>
      <inertia ixx="0.005000000000000001" ixy="0" ixz="0" iyy="0.08583333333333333" iyz="0" izz="0.08583333333333333"/>
    </inertial>
    <visual>
      <origin rpy="0 1.5707963267948966 0" xyz="0.5 0 0"/>
      <geometry>
        <cylinder length="1" radius="0.1"/>
      </geometry>
      <material name="">
        <color rgba="0.792156862745098 0.819607843137255 0.933333333333333 1"/>
      </material>
    </visual>
    <collision>
      <origin rpy="0 1.5707963267948966 0" xyz="0.5 0 0"/>
      <geometry>
        <cylinder length="1" radius="0.1"/>
      </geometry>
    </collision>
  </link>
  <joint name="RR_thigh_joint" type="continuous">
    <origin rpy="1.5707963267948966 0.0 -1.5707963267948966" xyz="0.25 0 0"/>
    <parent link="RR_hip"/>
    <child link="RR_thigh"/>
    <axis xyz="0 0 1"/>
  </joint>
  <link name="RR_calf">
    <inertial>
      <origin rpy="0 0 0" xyz="0.5 0 0"/>
      <mass value="1"/>
      <inertia ixx="0.005000000000000001" ixy="0" ixz="0" iyy="0.08583333333333333" iyz="0" izz="0.08583333333333333"/>
    </inertial>
    <visual>
      <origin rpy="0 1.5707963267948966 0" xyz="0.5 0 0"/>
      <geometry>
        <cylinder length="1" radius="0.1"/>
      </geometry>
      <material name="">
        <color rgba="0.792156862745098 0.819607843137255 0.933333333333333 1"/>
      </material>
    </visual>
    <collision>
      <origin rpy="0 1.5707963267948966 0" xyz="0.5 0 0"/>
      <geometry>
        <cylinder length="1" radius="0.1"/>
      </geometry>
    </collision>
  </link>
  <joint name="RR_calf_joint" type="continuous">
    <origin rpy="0.0 0.0 0.0" xyz="1 0 0"/>
    <parent link="RR_thigh"/>
    <child link="RR_calf"/>
    <axis xyz="0 0 1"/>
  </joint>
  <link name="RR_foot">
    <inertial>
      <origin rpy="0 0 0" xyz="0 0 0"/>
      <mass value="1"/>
      <inertia ixx="0.004000000000000001" ixy="0" ixz="0" iyy="0.0025937500000000006" iyz="0" izz="0.0025937500000000006"/>
    </inertial>
    <visual>
      <origin rpy="0 0 0" xyz="0 0 0"/>
      <geometry>
        <sphere radius="0.1"/>
      </geometry>
      <material name="">
        <color rgba="0.792156862745098 0.819607843137255 0.933333333333333 1"/>
      </material>
    </visual>
    <collision>
      <origin rpy="0 0 0" xyz="0 0 0"/>
      <geometry>
        <sphere radius="0.1"/>
      </geometry>
    </collision>
  </link>
  <joint name="RR_foot" type="fixed">
    <origin rpy="0.0 0.0 0.0" xyz="1 0 0"/>
    <parent link="RR_calf"/>
    <child link="RR_foot"/>
  </joint>
</robot>
